Workbook

Sheet Sheet1
A1: FOUR CORE CABLES | E1: SINGLE CORE CABLES
A3: CABLE SIZE mm² | B3: OVERALL DIA mm | C3: CSA mm² | E3: CABLE SIZE mm² | F3: OVERALL DIA mm | G3: CSA mm² | I3: 1.5 | L3: Single core | M3: LV
A4: M | B4: 0 | C4: 0 | E4: 0 | F4: 0 | G4: 0 | I4: 2.5 | L4: Multi core | M4: MV
A5: 1.5 | B5: 10.6 | C5: =3.14*(B5*B5/4) -> 88.2026 | E5: 4 | F5: 7 | G5: =3.14*(F5*F5/4) -> 38.465 | I5: 4
A6: 2.5 | B6: 11.9 | C6: =3.14*(B6*B6/4) -> 111.16385 | E6: 6 | F6: 7.9 | G6: =3.14*(F6*F6/4) -> 48.99185 | I6: 6
A7: 4 | B7: 13.4 | C7: =3.14*(B7*B7/4) -> 140.9546 | E7: 10 | F7: 8.9 | G7: =3.14*(F7*F7/4) -> 62.17985 | I7: 10
A8: 6 | B8: 14.6 | C8: =3.14*(B8*B8/4) -> 167.3306 | E8: 16 | F8: 9.9 | G8: =3.14*(F8*F8/4) -> 76.93785 | I8: 16
A9: 10 | B9: 17 | C9: =3.14*(B9*B9/4) -> 226.865 | E9: 25 | F9: 11.6 | G9: =3.14*(F9*F9/4) -> 105.6296 | I9: 25
A10: 16 | B10: 19.4 | C10: =3.14*(B10*B10/4) -> 295.4426 | E10: 35 | F10: 12.7 | G10: =3.14*(F10*F10/4) -> 126.61265 | I10: 35
A11: 25 | B11: 23.5 | C11: =3.14*(B11*B11/4) -> 433.51625 | E11: 50 | F11: 14.6 | G11: =3.14*(F11*F11/4) -> 167.3306 | I11: 50
A12: 35 | B12: 23.6 | C12: =3.14*(B12*B12/4) -> 437.2136 | E12: 70 | F12: 16.3 | G12: =3.14*(F12*F12/4) -> 208.56665 | I12: 70
A13: 50 | B13: 27.1 | C13: =3.14*(B13*B13/4) -> 576.51185 | E13: 95 | F13: 18.7 | G13: =3.14*(F13*F13/4) -> 274.50665 | I13: 95
A14: 70 | B14: 31.4 | C14: =3.14*(B14*B14/4) -> 773.9786 | E14: 120 | F14: 20.4 | G14: =3.14*(F14*F14/4) -> 326.6856 | I14: 120
A15: 95 | B15: 35.1 | C15: =3.14*(B15*B15/4) -> 967.12785 | E15: 150 | F15: 22.6 | G15: =3.14*(F15*F15/4) -> 400.9466 | I15: 150
A16: 120 | B16: 39.2 | C16: =3.14*(B16*B16/4) -> 1206.2624 | E16: 185 | F16: 24.9 | G16: =3.14*(F16*F16/4) -> 486.70785 | I16: 185
... A20: 300 | B20: 60.1 | C20: =3.14*(B20*B20/4) -> 2835.4279 | E20: 500 | F20: 38.8 | G20: =3.14*(F20*F20/4) -> 1181.7704 | I20: 500
E21: 630 | F21: 42.7 | G21: =3.14*(F21*F21/4) -> 1431.2827 | I21: 630
A22: FOUR CORE CABLES with Reduced Neutral | E22: 800 | F22: 47.2 | G22: =3.14*(F22*F22/4) -> 1748.8544 | I22: 800
E23: 1000 | F23: 52 | G23: =3.14*(F23*F23/4) -> 2122.64 | I23: 1000
A24: 35 | B24: 22.5 | C24: =3.14*(B24*B24/4) -> 397.40625
A25: 50 | B25: 25.9 | C25: =3.14*(B25*B25/4) -> 526.58585
A26: 70 | B26: 29.7 | C26: =3.14*(B26*B26/4) -> 692.44065
A27: 95 | B27: 33.6 | C27: =3.14*(B27*B27/4) -> 886.2336
A28: 120 | B28: 37.5 | C28: =3.14*(B28*B28/4) -> 1103.9062
A29: 150 | B29: 41.3 | C29: =3.14*(B29*B29/4) -> 1338.9666
A30: 185 | B30: 46.2 | C30: =3.14*(B30*B30/4) -> 1675.5354
A31: 240 | B31: 51.5 | C31: =3.14*(B31*B31/4) -> 2082.0163
A32: 300 | B32: 56.8 | C32: =3.14*(B32*B32/4) -> 2532.5984
B35: TABLE 392.22(A)
B37: WIDTH | C37: X1 | E37: X2 | G37: X3 | I37: X4 | K37: X5 | M37: X6 | O37: X7 | Q37: X8 | S37: X9 | U37: X10
B38: 50 | C38: 1500 | D38: =(C38-30*'Cable TRAY VER.1.1'!$I$35) -> -287040 | E38: =C38*2 -> 3000 | F38: =(E38-30*'Cable TRAY VER.1.1'!$I$35) -> -285540 | G38: =C38*3 -> 4500 | H38: =(G38-30*'Cable TRAY VER.1.1'!$I$35) -> -284040 | I38: =C38*4 -> 6000 | J38: =(I38-30*'Cable TRAY VER.1.1'!$I$35) -> -282540 | K38: =C38*5 -> 7500 | L38: =(K38-30*'Cable TRAY VER.1.1'!$I$35) -> -281040 | M38: =C38*6 -> 9000 | N38: =(M38-30*'Cable TRAY VER.1.1'!$I$35) -> -279540 | O38: =C38*7 -> 10500 | P38: =(O38-30*'Cable TRAY VER.1.1'!$I$35) -> -278040 | Q38: =C38*8 -> 12000 | R38: =(Q38-30*'Cable TRAY VER.1.1'!$I$35) -> -276540 | S38: =C38*9 -> 13500 | T38: =(S38-30*'Cable TRAY VER.1.1'!$I$35) -> -275040 | U38: =C38*10 -> 15000 | V38: =(U38-30*'Cable TRAY VER.1.1'!$I$35) -> -273540
B39: 100 | C39: 3000 | D39: =(C39-30*'Cable TRAY VER.1.1'!$I$35) -> -285540 | E39: =C39*2 -> 6000 | F39: =(E39-30*'Cable TRAY VER.1.1'!$I$35) -> -282540 | G39: =C39*3 -> 9000 | H39: =(G39-30*'Cable TRAY VER.1.1'!$I$35) -> -279540 | I39: =C39*4 -> 12000 | J39: =(I39-30*'Cable TRAY VER.1.1'!$I$35) -> -276540 | K39: =C39*5 -> 15000 | L39: =(K39-30*'Cable TRAY VER.1.1'!$I$35) -> -273540 | M39: =C39*6 -> 18000 | N39: =(M39-30*'Cable TRAY VER.1.1'!$I$35) -> -270540 | O39: =C39*7 -> 21000 | P39: =(O39-30*'Cable TRAY VER.1.1'!$I$35) -> -267540 | Q39: =C39*8 -> 24000 | R39: =(Q39-30*'Cable TRAY VER.1.1'!$I$35) -> -264540 | S39: =C39*9 -> 27000 | T39: =(S39-30*'Cable TRAY VER.1.1'!$I$35) -> -261540 | U39: =C39*10 -> 30000 | V39: =(U39-30*'Cable TRAY VER.1.1'!$I$35) -> -258540
B40: 150 | C40: 4500 | D40: =(C40-30*'Cable TRAY VER.1.1'!$I$35) -> -284040 | E40: =C40*2 -> 9000 | F40: =(E40-30*'Cable TRAY VER.1.1'!$I$35) -> -279540 | G40: =C40*3 -> 13500 | H40: =(G40-30*'Cable TRAY VER.1.1'!$I$35) -> -275040 | I40: =C40*4 -> 18000 | J40: =(I40-30*'Cable TRAY VER.1.1'!$I$35) -> -270540 | K40: =C40*5 -> 22500 | L40: =(K40-30*'Cable TRAY VER.1.1'!$I$35) -> -266040 | M40: =C40*6 -> 27000 | N40: =(M40-30*'Cable TRAY VER.1.1'!$I$35) -> -261540 | O40: =C40*7 -> 31500 | P40: =(O40-30*'Cable TRAY VER.1.1'!$I$35) -> -257040 | Q40: =C40*8 -> 36000 | R40: =(Q40-30*'Cable TRAY VER.1.1'!$I$35) -> -252540 | S40: =C40*9 -> 40500 | T40: =(S40-30*'Cable TRAY VER.1.1'!$I$35) -> -248040 | U40: =C40*10 -> 45000 | V40: =(U40-30*'Cable TRAY VER.1.1'!$I$35) -> -243540
B41: 200 | C41: 6000 | D41: =(C41-30*'Cable TRAY VER.1.1'!$I$35) -> -282540 | E41: =C41*2 -> 12000 | F41: =(E41-30*'Cable TRAY VER.1.1'!$I$35) -> -276540 | G41: =C41*3 -> 18000 | H41: =(G41-30*'Cable TRAY VER.1.1'!$I$35) -> -270540 | I41: =C41*4 -> 24000 | J41: =(I41-30*'Cable TRAY VER.1.1'!$I$35) -> -264540 | K41: =C41*5 -> 30000 | L41: =(K41-30*'Cable TRAY VER.1.1'!$I$35) -> -258540 | M41: =C41*6 -> 36000 | N41: =(M41-30*'Cable TRAY VER.1.1'!$I$35) -> -252540 | O41: =C41*7 -> 42000 | P41: =(O41-30*'Cable TRAY VER.1.1'!$I$35) -> -246540 | Q41: =C41*8 -> 48000 | R41: =(Q41-30*'Cable TRAY VER.1.1'!$I$35) -> -240540 | S41: =C41*9 -> 54000 | T41: =(S41-30*'Cable TRAY VER.1.1'!$I$35) -> -234540 | U41: =C41*10 -> 60000 | V41: =(U41-30*'Cable TRAY VER.1.1'!$I$35) -> -228540
B42: 225 | C42: 6800 | D42: =(C42-30*'Cable TRAY VER.1.1'!$I$35) -> -281740 | E42: =C42*2 -> 13600 | F42: =(E42-30*'Cable TRAY VER.1.1'!$I$35) -> -274940 | G42: =C42*3 -> 20400 | H42: =(G42-30*'Cable TRAY VER.1.1'!$I$35) -> -268140 | I42: =C42*4 -> 27200 | J42: =(I42-30*'Cable TRAY VER.1.1'!$I$35) -> -261340 | K42: =C42*5 -> 34000 | L42: =(K42-30*'Cable TRAY VER.1.1'!$I$35) -> -254540 | M42: =C42*6 -> 40800 | N42: =(M42-30*'Cable TRAY VER.1.1'!$I$35) -> -247740 | O42: =C42*7 -> 47600 | P42: =(O42-30*'Cable TRAY VER.1.1'!$I$35) -> -240940 | Q42: =C42*8 -> 54400 | R42: =(Q42-30*'Cable TRAY VER.1.1'!$I$35) -> -234140 | S42: =C42*9 -> 61200 | T42: =(S42-30*'Cable TRAY VER.1.1'!$I$35) -> -227340 | U42: =C42*10 -> 68000 | V42: =(U42-30*'Cable TRAY VER.1.1'!$I$35) -> -220540
B43: 300 | C43: 9000 | D43: =(C43-30*'Cable TRAY VER.1.1'!$I$35) -> -279540 | E43: =C43*2 -> 18000 | F43: =(E43-30*'Cable TRAY VER.1.1'!$I$35) -> -270540 | G43: =C43*3 -> 27000 | H43: =(G43-30*'Cable TRAY VER.1.1'!$I$35) -> -261540 | I43: =C43*4 -> 36000 | J43: =(I43-30*'Cable TRAY VER.1.1'!$I$35) -> -252540 | K43: =C43*5 -> 45000 | L43: =(K43-30*'Cable TRAY VER.1.1'!$I$35) -> -243540 | M43: =C43*6 -> 54000 | N43: =(M43-30*'Cable TRAY VER.1.1'!$I$35) -> -234540 | O43: =C43*7 -> 63000 | P43: =(O43-30*'Cable TRAY VER.1.1'!$I$35) -> -225540 | Q43: =C43*8 -> 72000 | R43: =(Q43-30*'Cable TRAY VER.1.1'!$I$35) -> -216540 | S43: =C43*9 -> 81000 | T43: =(S43-30*'Cable TRAY VER.1.1'!$I$35) -> -207540 | U43: =C43*10 -> 90000 | V43: =(U43-30*'Cable TRAY VER.1.1'!$I$35) -> -198540
B44: 400 | C44: 12000 | D44: =(C44-30*'Cable TRAY VER.1.1'!$I$35) -> -276540 | E44: =C44*2 -> 24000 | F44: =(E44-30*'Cable TRAY VER.1.1'!$I$35) -> -264540 | G44: =C44*3 -> 36000 | H44: =(G44-30*'Cable TRAY VER.1.1'!$I$35) -> -252540 | I44: =C44*4 -> 48000 | J44: =(I44-30*'Cable TRAY VER.1.1'!$I$35) -> -240540 | K44: =C44*5 -> 60000 | L44: =(K44-30*'Cable TRAY VER.1.1'!$I$35) -> -228540 | M44: =C44*6 -> 72000 | N44: =(M44-30*'Cable TRAY VER.1.1'!$I$35) -> -216540 | O44: =C44*7 -> 84000 | P44: =(O44-30*'Cable TRAY VER.1.1'!$I$35) -> -204540 | Q44: =C44*8 -> 96000 | R44: =(Q44-30*'Cable TRAY VER.1.1'!$I$35) -> -192540 | S44: =C44*9 -> 108000 | T44: =(S44-30*'Cable TRAY VER.1.1'!$I$35) -> -180540 | U44: =C44*10 -> 120000 | V44: =(U44-30*'Cable TRAY VER.1.1'!$I$35) -> -168540
B45: 450 | C45: 13500 | D45: =(C45-30*'Cable TRAY VER.1.1'!$I$35) -> -275040 | E45: =C45*2 -> 27000 | F45: =(E45-30*'Cable TRAY VER.1.1'!$I$35) -> -261540 | G45: =C45*3 -> 40500 | H45: =(G45-30*'Cable TRAY VER.1.1'!$I$35) -> -248040 | I45: =C45*4 -> 54000 | J45: =(I45-30*'Cable TRAY VER.1.1'!$I$35) -> -234540 | K45: =C45*5 -> 67500 | L45: =(K45-30*'Cable TRAY VER.1.1'!$I$35) -> -221040 | M45: =C45*6 -> 81000 | N45: =(M45-30*'Cable TRAY VER.1.1'!$I$35) -> -207540 | O45: =C45*7 -> 94500 | P45: =(O45-30*'Cable TRAY VER.1.1'!$I$35) -> -194040 | Q45: =C45*8 -> 108000 | R45: =(Q45-30*'Cable TRAY VER.1.1'!$I$35) -> -180540 | S45: =C45*9 -> 121500 | T45: =(S45-30*'Cable TRAY VER.1.1'!$I$35) -> -167040 | U45: =C45*10 -> 135000 | V45: =(U45-30*'Cable TRAY VER.1.1'!$I$35) -> -153540
B46: 500 | C46: 15000 | D46: =(C46-30*'Cable TRAY VER.1.1'!$I$35) -> -273540 | E46: =C46*2 -> 30000 | F46: =(E46-30*'Cable TRAY VER.1.1'!$I$35) -> -258540 | G46: =C46*3 -> 45000 | H46: =(G46-30*'Cable TRAY VER.1.1'!$I$35) -> -243540 | I46: =C46*4 -> 60000 | J46: =(I46-30*'Cable TRAY VER.1.1'!$I$35) -> -228540 | K46: =C46*5 -> 75000 | L46: =(K46-30*'Cable TRAY VER.1.1'!$I$35) -> -213540 | M46: =C46*6 -> 90000 | N46: =(M46-30*'Cable TRAY VER.1.1'!$I$35) -> -198540 | O46: =C46*7 -> 105000 | P46: =(O46-30*'Cable TRAY VER.1.1'!$I$35) -> -183540 | Q46: =C46*8 -> 120000 | R46: =(Q46-30*'Cable TRAY VER.1.1'!$I$35) -> -168540 | S46: =C46*9 -> 135000 | T46: =(S46-30*'Cable TRAY VER.1.1'!$I$35) -> -153540 | U46: =C46*10 -> 150000 | V46: =(U46-30*'Cable TRAY VER.1.1'!$I$35) -> -138540
B47: 600 | C47: 18000 | D47: =(C47-30*'Cable TRAY VER.1.1'!$I$35) -> -270540 | E47: =C47*2 -> 36000 | F47: =(E47-30*'Cable TRAY VER.1.1'!$I$35) -> -252540 | G47: =C47*3 -> 54000 | H47: =(G47-30*'Cable TRAY VER.1.1'!$I$35) -> -234540 | I47: =C47*4 -> 72000 | J47: =(I47-30*'Cable TRAY VER.1.1'!$I$35) -> -216540 | K47: =C47*5 -> 90000 | L47: =(K47-30*'Cable TRAY VER.1.1'!$I$35) -> -198540 | M47: =C47*6 -> 108000 | N47: =(M47-30*'Cable TRAY VER.1.1'!$I$35) -> -180540 | O47: =C47*7 -> 126000 | P47: =(O47-30*'Cable TRAY VER.1.1'!$I$35) -> -162540 | Q47: =C47*8 -> 144000 | R47: =(Q47-30*'Cable TRAY VER.1.1'!$I$35) -> -144540 | S47: =C47*9 -> 162000 | T47: =(S47-30*'Cable TRAY VER.1.1'!$I$35) -> -126540 | U47: =C47*10 -> 180000 | V47: =(U47-30*'Cable TRAY VER.1.1'!$I$35) -> -108540
...

Sheet Cable TRAY VER.1.1
B1: Notes: 1- Cable tray sizing based on NEC code section 392.22. 2- The allowable fill ratio of multi core cables approximately used for single core cables. 3- The cable sizes (mm2) as per the IEC standard. 4- The input data of the LV cables as per 2kv rating & non-armoured type. 5- The input data of the MV cables as per 22kv rating & armoured type.
B3: Warning text: | C3: =IF(ISNA(H35),"Incorrect cable sizes ","Please fill in the cells in white") -> Please fill in the cells in white
B4: STEP-1 | C4: STEP-2 | M4: STEP-4
B7: Low Voltage OR MV Cables | C7: NO. of Identical Cables | E7: Cable Data | H7: DIA(mm) FOR ONE CABLE | I7: TOTAL DIA(mm) FOR NO. OF CABLES | J7: CSA(mm2) FOR ONE CABLE | K7: CSA(mm2) FOR NO. OF CABLES | M7: Automatic
B10: MV | C10: 1 | D10: 1 | E10: Multi core | F10: 50 | G10: mm2 | H10: =IF(AND($B$10="LV",E10="SINGLE CORE"),VLOOKUP('Cable TRAY VER.1.1'!F10,Sheet1!$E$4:$F$23,2,0),IF(AND($B$10="LV",E10="MULTI CORE"),VLOOKUP(F10,Sheet1!$A$4:$B$20,2,0),IF(AND('Cable TRAY VER.1.1'!$B$10="MV",'Cable TRAY VER.1.1'!E10="SINGLE CORE"),VLOOKUP('Cable TRAY VER.1.1'!F10,Sheet1!$A$70:$L$81,12,0),IF(AND('Cable TRAY VER.1.1'!$B$10="MV",'Cable TRAY VER.1.1'!E10="MULTI CORE"),VLOOKUP('Cable TRAY VER.1.1'!F10,Sheet1!$A$87:$L$95,12,0),FALSE)))) -> 64 | I10: =H10*D10 -> 64 | J10: =3.14*H10*H10/4 -> 3215.36 | K10: =J10*D10 -> 3215.36 | M10: NO. OF PARALLEL CABLE TRAYS | O10: WIDTH (mm)
C11: 2 | D11: 100 | E11: Multi core | F11: 300 | G11: mm2 | H11: =IF(AND($B$10="LV",E11="SINGLE CORE"),VLOOKUP('Cable TRAY VER.1.1'!F11,Sheet1!$E$4:$F$23,2,0),IF(AND($B$10="LV",E11="MULTI CORE"),VLOOKUP(F11,Sheet1!$A$4:$B$20,2,0),IF(AND('Cable TRAY VER.1.1'!$B$10="MV",'Cable TRAY VER.1.1'!E11="SINGLE CORE"),VLOOKUP('Cable TRAY VER.1.1'!F11,Sheet1!$A$70:$L$81,12,0),IF(AND('Cable TRAY VER.1.1'!$B$10="MV",'Cable TRAY VER.1.1'!E11="MULTI CORE"),VLOOKUP('Cable TRAY VER.1.1'!F11,Sheet1!$A$87:$L$95,12,0),FALSE)))) -> 95 | I11: =H11*D11 -> 9500 | J11: =3.14*H11*H11/4 -> 7084.625 | K11: =J11*D11 -> 708462.5
C12: 3 | E12: Single core | F12: 50 | G12: mm2 | H12: =IF(AND($B$10="LV",E12="SINGLE CORE"),VLOOKUP('Cable TRAY VER.1.1'!F12,Sheet1!$E$4:$F$23,2,0),IF(AND($B$10="LV",E12="MULTI CORE"),VLOOKUP(F12,Sheet1!$A$4:$B$20,2,0),IF(AND('Cable TRAY VER.1.1'!$B$10="MV",'Cable TRAY VER.1.1'!E12="SINGLE CORE"),VLOOKUP('Cable TRAY VER.1.1'!F12,Sheet1!$A$70:$L$81,12,0),IF(AND('Cable TRAY VER.1.1'!$B$10="MV",'Cable TRAY VER.1.1'!E12="MULTI CORE"),VLOOKUP('Cable TRAY VER.1.1'!F12,Sheet1!$A$87:$L$95,12,0),FALSE)))) -> 36 | I12: =H12*D12 -> 0 | J12: =3.14*H12*H12/4 -> 1017.36 | K12: =J12*D12 -> 0
C13: 4 | D13: 1 | E13: Single core | F13: 400 | G13: mm2 | H13: =IF(AND($B$10="LV",E13="SINGLE CORE"),VLOOKUP('Cable TRAY VER.1.1'!F13,Sheet1!$E$4:$F$23,2,0),IF(AND($B$10="LV",E13="MULTI CORE"),VLOOKUP(F13,Sheet1!$A$4:$B$20,2,0),IF(AND('Cable TRAY VER.1.1'!$B$10="MV",'Cable TRAY VER.1.1'!E13="SINGLE CORE"),VLOOKUP('Cable TRAY VER.1.1'!F13,Sheet1!$A$70:$L$81,12,0),IF(AND('Cable TRAY VER.1.1'!$B$10="MV",'Cable TRAY VER.1.1'!E13="MULTI CORE"),VLOOKUP('Cable TRAY VER.1.1'!F13,Sheet1!$A$87:$L$95,12,0),FALSE)))) -> 54 | I13: =H13*D13 -> 54 | J13: =3.14*H13*H13/4 -> 2289.06 | K13: =J13*D13 -> 2289.06 | M13: =IF(B10="LV",Q13,Q14) -> More than 10 trays too much | O13: =IF(B10="LV",P13,P14) -> 900 | P13: =IF(AND(MAX(F10:F34)<95,K35<Sheet1!C38),50,IF(AND(MAX(F10:F34)<95,K35<Sheet1!C39),100,IF(AND(MAX(F10:F34)<95,K35<Sheet1!C40),150,IF(AND(MAX(F10:F34)<95,K35<Sheet1!C41),200,IF(AND(MAX(F10:F34)<95,K35<Sheet1!C42),225,IF(AND(MAX(F10:F34)<95,K35<Sheet1!C43),300,IF(AND(MAX(F10:F34)<95,K35<Sheet1!C44),400,IF(AND(MAX(F10:F34)<95,K35<Sheet1!C45),450,IF(AND(MAX(F10:F34)<95,K35<Sheet1!C46),500,IF(AND(MAX(F10:F34)<95,K35<Sheet1!C47),600,IF(AND(MAX(F10:F34)<95,K35<Sheet1!C48),750,IF(AND(MAX(F10:F34)<95,K35<Sheet1!C49),900,IF(AND(MAX(F10:F34)<95,Sheet1!C49<K35),900,IF(AND(95<=MAX(F10:F34),K35<Sheet1!D38),50,IF(AND(95<=MAX(F10:F34),K35<Sheet1!D39),100,IF(AND(95<=MAX(F10:F34),K35<Sheet1!D40),150,IF(AND(95<=MAX(F10:F34),K35<Sheet1!D41),200,IF(AND(95<=MAX(F10:F34),K35<Sheet1!D42),225,IF(AND(95<=MAX(F10:F34),K35<Sheet1!D43),300,IF(AND(95<=MAX(F10:F34),K35<Sheet1!D44),400,IF(AND(95<=MAX(F10:F34),K35<Sheet1!D45),450,IF(AND(95<=MAX(F10:F34),K35<Sheet1!D46),500,IF(AND(95<=MAX(F10:F34),K35<Sheet1!D47),600,IF(AND(95<=MAX(F10:F34),K35<Sheet1!D48),750,IF(AND(95<=MAX(F10:F34),K35<Sheet1!D49),900,IF(AND(95<=MAX(F10:F34),Sheet1!D49<=K35),900,1)))))))))))))))))))))))))) -> 900 | Q13: =IF(AND(MAX(F10:F34)<95,K35<Sheet1!C49),1,IF(AND(MAX(F10:F34)<95,K35<Sheet1!E49),2,IF(AND(MAX(F10:F34)<95,K35<Sheet1!G49),3,IF(AND(MAX(F10:F34)<95,K35<Sheet1!I49),4,IF(AND(MAX(F10:F34)<95,K35<Sheet1!K49),5,IF(AND(MAX(F10:F34)<95,K35<Sheet1!M49),6,IF(AND(MAX(F10:F34)<95,K35<Sheet1!O49),7,IF(AND(MAX(F10:F34)<95,K35<Sheet1!Q49),8,IF(AND(MAX(F10:F34)<95,K35<Sheet1!S49),9,IF(AND(MAX(F10:F34)<95,K35<Sheet1!U49),10,IF(AND(95<=MAX(F10:F34),K35<Sheet1!D49),1,IF(AND(95<=MAX(F10:F34),K35<Sheet1!F49),2,IF(AND(95<=MAX(F10:F34),K35<Sheet1!H49),3,IF(AND(95<=MAX(F10:F34),K35<Sheet1!J49),4,IF(AND(95<=MAX(F10:F34),K35<Sheet1!L49),5,IF(AND(95<=MAX(F10:F34),K35<Sheet1!N49),6,IF(AND(95<=MAX(F10:F34),K35<Sheet1!P49),7,IF(AND(95<=MAX(F10:F34),K35<Sheet1!R49),8,IF(AND(95<=MAX(F10:F34),K35<Sheet1!T49),9,IF(AND(95<=MAX(F10:F34),K35<Sheet1!V49),10,"More than 10 trays too much")))))))))))))))))))) -> More than 10 trays too much | R13: LV
C14: 5 | E14: Single core | F14: 50 | G14: mm2 | H14: =IF(AND($B$10="LV",E14="SINGLE CORE"),VLOOKUP('Cable TRAY VER.1.1'!F14,Sheet1!$E$4:$F$23,2,0),IF(AND($B$10="LV",E14="MULTI CORE"),VLOOKUP(F14,Sheet1!$A$4:$B$20,2,0),IF(AND('Cable TRAY VER.1.1'!$B$10="MV",'Cable TRAY VER.1.1'!E14="SINGLE CORE"),VLOOKUP('Cable TRAY VER.1.1'!F14,Sheet1!$A$70:$L$81,12,0),IF(AND('Cable TRAY VER.1.1'!$B$10="MV",'Cable TRAY VER.1.1'!E14="MULTI CORE"),VLOOKUP('Cable TRAY VER.1.1'!F14,Sheet1!$A$87:$L$95,12,0),FALSE)))) -> 36 | I14: =H14*D14 -> 0 | J14: =3.14*H14*H14/4 -> 1017.36 | K14: =J14*D14 -> 0 | P14: =IF(I35<50,50,IF(I35<100,100,IF(I35<150,150,IF(I35<200,200,IF(I35<225,225,IF(I35<300,300,IF(I35<400,400,IF(I35<450,450,IF(I35<500,500,IF(I35<600,600,IF(I35<750,750,IF(I35<900,900,IF(900<=I35,900,FALSE))))))))))))) -> 900 | Q14: =IF(I35<900,1,IF(I35<1800,2,IF(I35<2700,3,IF(I35<3600,4,IF(I35<4500,5,IF(I35<5400,6,IF(I35<6300,7,IF(I35<7200,8,IF(I35<8100,9,IF(I35<9000,10,"More than 10 trays too much")))))))))) -> More than 10 trays too much | R14: MV
C15: 6 | E15: Single core | F15: 50 | G15: mm2 | H15: =IF(AND($B$10="LV",E15="SINGLE CORE"),VLOOKUP('Cable TRAY VER.1.1'!F15,Sheet1!$E$4:$F$23,2,0),IF(AND($B$10="LV",E15="MULTI CORE"),VLOOKUP(F15,Sheet1!$A$4:$B$20,2,0),IF(AND('Cable TRAY VER.1.1'!$B$10="MV",'Cable TRAY VER.1.1'!E15="SINGLE CORE"),VLOOKUP('Cable TRAY VER.1.1'!F15,Sheet1!$A$70:$L$81,12,0),IF(AND('Cable TRAY VER.1.1'!$B$10="MV",'Cable TRAY VER.1.1'!E15="MULTI CORE"),VLOOKUP('Cable TRAY VER.1.1'!F15,Sheet1!$A$87:$L$95,12,0),FALSE)))) -> 36 | I15: =H15*D15 -> 0 | J15: =3.14*H15*H15/4 -> 1017.36 | K15: =J15*D15 -> 0
C16: 7 | E16: Single core | F16: 50 | G16: mm2 | H16: =IF(AND($B$10="LV",E16="SINGLE CORE"),VLOOKUP('Cable TRAY VER.1.1'!F16,Sheet1!$E$4:$F$23,2,0),IF(AND($B$10="LV",E16="MULTI CORE"),VLOOKUP(F16,Sheet1!$A$4:$B$20,2,0),IF(AND('Cable TRAY VER.1.1'!$B$10="MV",'Cable TRAY VER.1.1'!E16="SINGLE CORE"),VLOOKUP('Cable TRAY VER.1.1'!F16,Sheet1!$A$70:$L$81,12,0),IF(AND('Cable TRAY VER.1.1'!$B$10="MV",'Cable TRAY VER.1.1'!E16="MULTI CORE"),VLOOKUP('Cable TRAY VER.1.1'!F16,Sheet1!$A$87:$L$95,12,0),FALSE)))) -> 36 | I16: =H16*D16 -> 0 | J16: =3.14*H16*H16/4 -> 1017.36 | K16: =J16*D16 -> 0
C17: 8 | E17: Single core | F17: 50 | G17: mm2 | H17: =IF(AND($B$10="LV",E17="SINGLE CORE"),VLOOKUP('Cable TRAY VER.1.1'!F17,Sheet1!$E$4:$F$23,2,0),IF(AND($B$10="LV",E17="MULTI CORE"),VLOOKUP(F17,Sheet1!$A$4:$B$20,2,0),IF(AND('Cable TRAY VER.1.1'!$B$10="MV",'Cable TRAY VER.1.1'!E17="SINGLE CORE"),VLOOKUP('Cable TRAY VER.1.1'!F17,Sheet1!$A$70:$L$81,12,0),IF(AND('Cable TRAY VER.1.1'!$B$10="MV",'Cable TRAY VER.1.1'!E17="MULTI CORE"),VLOOKUP('Cable TRAY VER.1.1'!F17,Sheet1!$A$87:$L$95,12,0),FALSE)))) -> 36 | I17: =H17*D17 -> 0 | J17: =3.14*H17*H17/4 -> 1017.36 | K17: =J17*D17 -> 0 | M17: Manual (SELECT TRAY WIDTH BEFORE)
C18: 9 | E18: Single core | F18: 50 | G18: mm2 | H18: =IF(AND($B$10="LV",E18="SINGLE CORE"),VLOOKUP('Cable TRAY VER.1.1'!F18,Sheet1!$E$4:$F$23,2,0),IF(AND($B$10="LV",E18="MULTI CORE"),VLOOKUP(F18,Sheet1!$A$4:$B$20,2,0),IF(AND('Cable TRAY VER.1.1'!$B$10="MV",'Cable TRAY VER.1.1'!E18="SINGLE CORE"),VLOOKUP('Cable TRAY VER.1.1'!F18,Sheet1!$A$70:$L$81,12,0),IF(AND('Cable TRAY VER.1.1'!$B$10="MV",'Cable TRAY VER.1.1'!E18="MULTI CORE"),VLOOKUP('Cable TRAY VER.1.1'!F18,Sheet1!$A$87:$L$95,12,0),FALSE)))) -> 36 | I18: =H18*D18 -> 0 | J18: =3.14*H18*H18/4 -> 1017.36 | K18: =J18*D18 -> 0
C19: 10 | E19: Single core | F19: 50 | G19: mm2 | H19: =IF(AND($B$10="LV",E19="SINGLE CORE"),VLOOKUP('Cable TRAY VER.1.1'!F19,Sheet1!$E$4:$F$23,2,0),IF(AND($B$10="LV",E19="MULTI CORE"),VLOOKUP(F19,Sheet1!$A$4:$B$20,2,0),IF(AND('Cable TRAY VER.1.1'!$B$10="MV",'Cable TRAY VER.1.1'!E19="SINGLE CORE"),VLOOKUP('Cable TRAY VER.1.1'!F19,Sheet1!$A$70:$L$81,12,0),IF(AND('Cable TRAY VER.1.1'!$B$10="MV",'Cable TRAY VER.1.1'!E19="MULTI CORE"),VLOOKUP('Cable TRAY VER.1.1'!F19,Sheet1!$A$87:$L$95,12,0),FALSE)))) -> 36 | I19: =H19*D19 -> 0 | J19: =3.14*H19*H19/4 -> 1017.36 | K19: =J19*D19 -> 0
C20: 11 | E20: Single core | F20: 50 | G20: mm2 | H20: =IF(AND($B$10="LV",E20="SINGLE CORE"),VLOOKUP('Cable TRAY VER.1.1'!F20,Sheet1!$E$4:$F$23,2,0),IF(AND($B$10="LV",E20="MULTI CORE"),VLOOKUP(F20,Sheet1!$A$4:$B$20,2,0),IF(AND('Cable TRAY VER.1.1'!$B$10="MV",'Cable TRAY VER.1.1'!E20="SINGLE CORE"),VLOOKUP('Cable TRAY VER.1.1'!F20,Sheet1!$A$70:$L$81,12,0),IF(AND('Cable TRAY VER.1.1'!$B$10="MV",'Cable TRAY VER.1.1'!E20="MULTI CORE"),VLOOKUP('Cable TRAY VER.1.1'!F20,Sheet1!$A$87:$L$95,12,0),FALSE)))) -> 36 | I20: =H20*D20 -> 0 | J20: =3.14*H20*H20/4 -> 1017.36 | K20: =J20*D20 -> 0 | M20: NO. OF PARALLEL CABLE TRAYS | O20: WIDTH (mm)
C21: 12 | E21: Single core | F21: 50 | G21: mm2 | H21: =IF(AND($B$10="LV",E21="SINGLE CORE"),VLOOKUP('Cable TRAY VER.1.1'!F21,Sheet1!$E$4:$F$23,2,0),IF(AND($B$10="LV",E21="MULTI CORE"),VLOOKUP(F21,Sheet1!$A$4:$B$20,2,0),IF(AND('Cable TRAY VER.1.1'!$B$10="MV",'Cable TRAY VER.1.1'!E21="SINGLE CORE"),VLOOKUP('Cable TRAY VER.1.1'!F21,Sheet1!$A$70:$L$81,12,0),IF(AND('Cable TRAY VER.1.1'!$B$10="MV",'Cable TRAY VER.1.1'!E21="MULTI CORE"),VLOOKUP('Cable TRAY VER.1.1'!F21,Sheet1!$A$87:$L$95,12,0),FALSE)))) -> 36 | I21: =H21*D21 -> 0 | J21: =3.14*H21*H21/4 -> 1017.36 | K21: =J21*D21 -> 0
C22: 13 | E22: Single core | F22: 50 | G22: mm2 | H22: =IF(AND($B$10="LV",E22="SINGLE CORE"),VLOOKUP('Cable TRAY VER.1.1'!F22,Sheet1!$E$4:$F$23,2,0),IF(AND($B$10="LV",E22="MULTI CORE"),VLOOKUP(F22,Sheet1!$A$4:$B$20,2,0),IF(AND('Cable TRAY VER.1.1'!$B$10="MV",'Cable TRAY VER.1.1'!E22="SINGLE CORE"),VLOOKUP('Cable TRAY VER.1.1'!F22,Sheet1!$A$70:$L$81,12,0),IF(AND('Cable TRAY VER.1.1'!$B$10="MV",'Cable TRAY VER.1.1'!E22="MULTI CORE"),VLOOKUP('Cable TRAY VER.1.1'!F22,Sheet1!$A$87:$L$95,12,0),FALSE)))) -> 36 | I22: =H22*D22 -> 0 | J22: =3.14*H22*H22/4 -> 1017.36 | K22: =J22*D22 -> 0 | P22: LV | R22: MV
C23: 14 | E23: Single core | F23: 50 | G23: mm2 | H23: =IF(AND($B$10="LV",E23="SINGLE CORE"),VLOOKUP('Cable TRAY VER.1.1'!F23,Sheet1!$E$4:$F$23,2,0),IF(AND($B$10="LV",E23="MULTI CORE"),VLOOKUP(F23,Sheet1!$A$4:$B$20,2,0),IF(AND('Cable TRAY VER.1.1'!$B$10="MV",'Cable TRAY VER.1.1'!E23="SINGLE CORE"),VLOOKUP('Cable TRAY VER.1.1'!F23,Sheet1!$A$70:$L$81,12,0),IF(AND('Cable TRAY VER.1.1'!$B$10="MV",'Cable TRAY VER.1.1'!E23="MULTI CORE"),VLOOKUP('Cable TRAY VER.1.1'!F23,Sheet1!$A$87:$L$95,12,0),FALSE)))) -> 36 | I23: =H23*D23 -> 0 | J23: =3.14*H23*H23/4 -> 1017.36 | K23: =J23*D23 -> 0 | M23: =IF(B10="LV",Q23,R23) -> More than 10 trays too much | O23: 600 | P23: =IF(AND(MAX(F10:F34)<95,O23=50,K35<Sheet1!C38),1,IF(AND(MAX(F10:F34)<95,O23=50,K35<Sheet1!E38),2,IF(AND(MAX(F10:F34)<95,O23=50,K35<Sheet1!G38),3,IF(AND(MAX(F10:F34)<95,O23=50,K35<Sheet1!I38),4,IF(AND(MAX(F10:F34)<95,O23=50,K35<Sheet1!K38),5,IF(AND(MAX(F10:F34)<95,O23=50,K35<Sheet1!M38),6,IF(AND(MAX(F10:F34)<95,O23=50,K35<Sheet1!O38),7,IF(AND(MAX(F10:F34)<95,O23=50,K35<Sheet1!Q38),8,IF(AND(MAX(F10:F34)<95,O23=50,K35<Sheet1!S38),9,IF(AND(MAX(F10:F34)<95,O23=50,K35<Sheet1!U38),10,IF(AND(MAX(F10:F34)<95,O23=100,K35<Sheet1!C39),1,IF(AND(MAX(F10:F34)<95,O23=100,K35<Sheet1!E39),2,IF(AND(MAX(F10:F34)<95,O23=100,K35<Sheet1!G39),3,IF(AND(MAX(F10:F34)<95,O23=100,K35<Sheet1!I39),4,IF(AND(MAX(F10:F34)<95,O23=100,K35<Sheet1!K39),5,IF(AND(MAX(F10:F34)<95,O23=100,K35<Sheet1!M39),6,IF(AND(MAX(F10:F34)<95,O23=100,K35<Sheet1!O39),7,IF(AND(MAX(F10:F34)<95,O23=100,K35<Sheet1!Q39),8,IF(AND(MAX(F10:F34)<95,O23=100,K35<Sheet1!S39),9,IF(AND(MAX(F10:F34)<95,O23=100,K35<Sheet1!U39),10,IF(AND(MAX(F10:F34)<95,O23=150,K35<Sheet1!C40),1,IF(AND(MAX(F10:F34)<95,O23=150,K35<Sheet1!E40),2,IF(AND(MAX(F10:F34)<95,O23=150,K35<Sheet1!G40),3,IF(AND(MAX(F10:F34)<95,O23=150,K35<Sheet1!I40),4,IF(AND(MAX(F10:F34)<95,O23=150,K35<Sheet1!K40),5,IF(AND(MAX(F10:F34)<95,O23=150,K35<Sheet1!M40),6,IF(AND(MAX(F10:F34)<95,O23=150,K35<Sheet1!O40),7,IF(AND(MAX(F10:F34)<95,O23=150,K35<Sheet1!Q40),8,IF(AND(MAX(F10:F34)<95,O23=150,K35<Sheet1!S40),9,IF(AND(MAX(F10:F34)<95,O23=150,K35<Sheet1!U40),10,IF(AND(MAX(F10:F34)<95,O23=200,K35<Sheet1!C41),1,IF(AND(MAX(F10:F34)<95,O23=200,K35<Sheet1!E41),2,IF(AND(MAX(F10:F34)<95,O23=200,K35<Sheet1!G41),3,IF(AND(MAX(F10:F34)<95,O23=200,K35<Sheet1!I41),4,IF(AND(MAX(F10:F34)<95,O23=200,K35<Sheet1!K41),5,IF(AND(MAX(F10:F34)<95,O23=200,K35<Sheet1!M41),6,IF(AND(MAX(F10:F34)<95,O23=200,K35<Sheet1!O41),7,IF(AND(MAX(F10:F34)<95,O23=200,K35<Sheet1!Q41),8,IF(AND(MAX(F10:F34)<95,O23=200,K35<Sheet1!S41),9,IF(AND(MAX(F10:F34)<95,O23=200,K35<Sheet1!U41),10,IF(AND(MAX(F10:F34)<95,O23=225,K35<Sheet1!C42),1,IF(AND(MAX(F10:F34)<95,O23=225,K35<Sheet1!E42),2,IF(AND(MAX(F10:F34)<95,O23=225,K35<Sheet1!G42),3,IF(AND(MAX(F10:F34)<95,O23=225,K35<Sheet1!I42),4,IF(AND(MAX(F10:F34)<95,O23=225,K35<Sheet1!K42),5,IF(AND(MAX(F10:F34)<95,O23=225,K35<Sheet1!M42),6,IF(AND(MAX(F10:F34)<95,O23=225,K35<Sheet1!O42),7,IF(AND(MAX(F10:F34)<95,O23=225,K35<Sheet1!Q42),8,IF(AND(MAX(F10:F34)<95,O23=225,K35<Sheet1!S42),9,IF(AND(MAX(F10:F34)<95,O23=225,K35<Sheet1!U42),10,IF(AND(MAX(F10:F34)<95,O23=300,K35<Sheet1!C43),1,IF(AND(MAX(F10:F34)<95,O23=300,K35<Sheet1!E43),2,IF(AND(MAX(F10:F34)<95,O23=300,K35<Sheet1!G43),3,IF(AND(MAX(F10:F34)<95,O23=300,K35<Sheet1!I43),4,IF(AND(MAX(F10:F34)<95,O23=300,K35<Sheet1!K43),5,IF(AND(MAX(F10:F34)<95,O23=300,K35<Sheet1!M43),6,IF(AND(MAX(F10:F34)<95,O23=300,K35<Sheet1!O43),7,IF(AND(MAX(F10:F34)<95,O23=300,K35<Sheet1!Q43),8,IF(AND(MAX(F10:F34)<95,O23=300,K35<Sheet1!S43),9,IF(AND(MAX(F10:F34)<95,O23=300,K35<Sheet1!U43),10,FALSE)))))))))))))))))))))))))))))))))))))))))))))))))))))))))))) -> FALSE | Q23: =IF(P27=0,"More than 10 trays too much",P27) -> More than 10 trays too much | R23: =IF(I35<O23,1,IF(I35<O23*2,2,IF(I35<O23*3,3,IF(I35<O23*4,4,IF(I35<O23*5,5,IF(I35<O23*6,6,IF(I35<O23*7,7,IF(I35<O23*8,8,IF(I35<O23*9,9,IF(I35<O23*10,10,"More than 10 trays too much")))))))))) -> More than 10 trays too much
C24: 15 | E24: Single core | F24: 50 | G24: mm2 | H24: =IF(AND($B$10="LV",E24="SINGLE CORE"),VLOOKUP('Cable TRAY VER.1.1'!F24,Sheet1!$E$4:$F$23,2,0),IF(AND($B$10="LV",E24="MULTI CORE"),VLOOKUP(F24,Sheet1!$A$4:$B$20,2,0),IF(AND('Cable TRAY VER.1.1'!$B$10="MV",'Cable TRAY VER.1.1'!E24="SINGLE CORE"),VLOOKUP('Cable TRAY VER.1.1'!F24,Sheet1!$A$70:$L$81,12,0),IF(AND('Cable TRAY VER.1.1'!$B$10="MV",'Cable TRAY VER.1.1'!E24="MULTI CORE"),VLOOKUP('Cable TRAY VER.1.1'!F24,Sheet1!$A$87:$L$95,12,0),FALSE)))) -> 36 | I24: =H24*D24 -> 0 | J24: =3.14*H24*H24/4 -> 1017.36 | K24: =J24*D24 -> 0 | P24: =IF(AND(MAX(F10:F34)<95,O23=400,K35<Sheet1!C44),1,IF(AND(MAX(F10:F34)<95,O23=400,K35<Sheet1!E44),2,IF(AND(MAX(F10:F34)<95,O23=400,K35<Sheet1!G44),3,IF(AND(MAX(F10:F34)<95,O23=400,K35<Sheet1!I44),4,IF(AND(MAX(F10:F34)<95,O23=400,K35<Sheet1!K44),5,IF(AND(MAX(F10:F34)<95,O23=400,K35<Sheet1!M44),6,IF(AND(MAX(F10:F34)<95,O23=400,K35<Sheet1!O44),7,IF(AND(MAX(F10:F34)<95,O23=400,K35<Sheet1!Q44),8,IF(AND(MAX(F10:F34)<95,O23=400,K35<Sheet1!S44),9,IF(AND(MAX(F10:F34)<95,O23=400,K35<Sheet1!U44),10,IF(AND(MAX(F10:F34)<95,O23=450,K35<Sheet1!C45),1,IF(AND(MAX(F10:F34)<95,O23=450,K35<Sheet1!E45),2,IF(AND(MAX(F10:F34)<95,O23=450,K35<Sheet1!G45),3,IF(AND(MAX(F10:F34)<95,O23=450,K35<Sheet1!I45),4,IF(AND(MAX(F10:F34)<95,O23=450,K35<Sheet1!K45),5,IF(AND(MAX(F10:F34)<95,O23=450,K35<Sheet1!M45),6,IF(AND(MAX(F10:F34)<95,O23=450,K35<Sheet1!O45),7,IF(AND(MAX(F10:F34)<95,O23=450,K35<Sheet1!Q45),8,IF(AND(MAX(F10:F34)<95,O23=450,K35<Sheet1!S45),9,IF(AND(MAX(F10:F34)<95,O23=450,K35<Sheet1!U45),10,IF(AND(MAX(F10:F34)<95,O23=500,K35<Sheet1!C46),1,IF(AND(MAX(F10:F34)<95,O23=500,K35<Sheet1!E46),2,IF(AND(MAX(F10:F34)<95,O23=500,K35<Sheet1!G46),3,IF(AND(MAX(F10:F34)<95,O23=500,K35<Sheet1!I46),4,IF(AND(MAX(F10:F34)<95,O23=500,K35<Sheet1!K46),5,IF(AND(MAX(F10:F34)<95,O23=500,K35<Sheet1!M46),6,IF(AND(MAX(F10:F34)<95,O23=500,K35<Sheet1!O46),7,IF(AND(MAX(F10:F34)<95,O23=500,K35<Sheet1!Q46),8,IF(AND(MAX(F10:F34)<95,O23=500,K35<Sheet1!S46),9,IF(AND(MAX(F10:F34)<95,O23=500,K35<Sheet1!U46),10,IF(AND(MAX(F10:F34)<95,O23=600,K35<Sheet1!C47),1,IF(AND(MAX(F10:F34)<95,O23=600,K35<Sheet1!E47),2,IF(AND(MAX(F10:F34)<95,O23=600,K35<Sheet1!G47),3,IF(AND(MAX(F10:F34)<95,O23=600,K35<Sheet1!I47),4,IF(AND(MAX(F10:F34)<95,O23=600,K35<Sheet1!K47),5,IF(AND(MAX(F10:F34)<95,O23=600,K35<Sheet1!M47),6,IF(AND(MAX(F10:F34)<95,O23=600,K35<Sheet1!O47),7,IF(AND(MAX(F10:F34)<95,O23=600,K35<Sheet1!Q47),8,IF(AND(MAX(F10:F34)<95,O23=600,K35<Sheet1!S47),9,IF(AND(MAX(F10:F34)<95,O23=600,K35<Sheet1!U47),10,IF(AND(MAX(F10:F34)<95,O23=750,K35<Sheet1!C48),1,IF(AND(MAX(F10:F34)<95,O23=750,K35<Sheet1!E48),2,IF(AND(MAX(F10:F34)<95,O23=750,K35<Sheet1!G48),3,IF(AND(MAX(F10:F34)<95,O23=750,K35<Sheet1!I48),4,IF(AND(MAX(F10:F34)<95,O23=750,K35<Sheet1!K48),5,IF(AND(MAX(F10:F34)<95,O23=750,K35<Sheet1!M48),6,IF(AND(MAX(F10:F34)<95,O23=750,K35<Sheet1!O48),7,IF(AND(MAX(F10:F34)<95,O23=750,K35<Sheet1!Q48),8,IF(AND(MAX(F10:F34)<95,O23=750,K35<Sheet1!S48),9,IF(AND(MAX(F10:F34)<95,O23=750,K35<Sheet1!U48),10,IF(AND(MAX(F10:F34)<95,O23=900,K35<Sheet1!C49),1,IF(AND(MAX(F10:F34)<95,O23=900,K35<Sheet1!E49),2,IF(AND(MAX(F10:F34)<95,O23=900,K35<Sheet1!G49),3,IF(AND(MAX(F10:F34)<95,O23=900,K35<Sheet1!I49),4,IF(AND(MAX(F10:F34)<95,O23=900,K35<Sheet1!K49),5,IF(AND(MAX(F10:F34)<95,O23=900,K35<Sheet1!M49),6,IF(AND(MAX(F10:F34)<95,O23=900,K35<Sheet1!O49),7,IF(AND(MAX(F10:F34)<95,O23=900,K35<Sheet1!Q49),8,IF(AND(MAX(F10:F34)<95,O23=900,K35<Sheet1!S49),9,IF(AND(MAX(F10:F34)<95,O23=900,K35<Sheet1!U49),10,FALSE)))))))))))))))))))))))))))))))))))))))))))))))))))))))))))) -> FALSE
C25: 16 | E25: Single core | F25: 50 | G25: mm2 | H25: =IF(AND($B$10="LV",E25="SINGLE CORE"),VLOOKUP('Cable TRAY VER.1.1'!F25,Sheet1!$E$4:$F$23,2,0),IF(AND($B$10="LV",E25="MULTI CORE"),VLOOKUP(F25,Sheet1!$A$4:$B$20,2,0),IF(AND('Cable TRAY VER.1.1'!$B$10="MV",'Cable TRAY VER.1.1'!E25="SINGLE CORE"),VLOOKUP('Cable TRAY VER.1.1'!F25,Sheet1!$A$70:$L$81,12,0),IF(AND('Cable TRAY VER.1.1'!$B$10="MV",'Cable TRAY VER.1.1'!E25="MULTI CORE"),VLOOKUP('Cable TRAY VER.1.1'!F25,Sheet1!$A$87:$L$95,12,0),FALSE)))) -> 36 | I25: =H25*D25 -> 0 | J25: =3.14*H25*H25/4 -> 1017.36 | K25: =J25*D25 -> 0 | P25: =IF(AND(95<=MAX(F10:F34),O23=50,K35<Sheet1!D38),1,IF(AND(95<=MAX(F10:F34),O23=50,K35<Sheet1!F38),2,IF(AND(95<=MAX(F10:F34),O23=50,K35<Sheet1!H38),3,IF(AND(95<=MAX(F10:F34),O23=50,K35<Sheet1!J38),4,IF(AND(95<=MAX(F10:F34),O23=50,K35<Sheet1!L38),5,IF(AND(95<=MAX(F10:F34),O23=50,K35<Sheet1!N38),6,IF(AND(95<=MAX(F10:F34),O23=50,K35<Sheet1!P38),7,IF(AND(95<=MAX(F10:F34),O23=50,K35<Sheet1!R38),8,IF(AND(95<=MAX(F10:F34),O23=50,K35<Sheet1!T38),9,IF(AND(95<=MAX(F10:F34),O23=50,K35<Sheet1!V38),10,IF(AND(95<=MAX(F10:F34),O23=100,K35<Sheet1!D39),1,IF(AND(95<=MAX(F10:F34),O23=100,K35<Sheet1!F39),2,IF(AND(95<=MAX(F10:F34),O23=100,K35<Sheet1!H39),3,IF(AND(95<=MAX(F10:F34),O23=100,K35<Sheet1!J39),4,IF(AND(95<=MAX(F10:F34),O23=100,K35<Sheet1!L39),5,IF(AND(95<=MAX(F10:F34),O23=100,K35<Sheet1!N39),6,IF(AND(95<=MAX(F10:F34),O23=100,K35<Sheet1!P39),7,IF(AND(95<=MAX(F10:F34),O23=100,K35<Sheet1!R39),8,IF(AND(95<=MAX(F10:F34),O23=100,K35<Sheet1!T39),9,IF(AND(95<=MAX(F10:F34),O23=100,K35<Sheet1!V39),10,IF(AND(95<=MAX(F10:F34),O23=150,K35<Sheet1!D40),1,IF(AND(95<=MAX(F10:F34),O23=150,K35<Sheet1!F40),2,IF(AND(95<=MAX(F10:F34),O23=150,K35<Sheet1!H40),3,IF(AND(95<=MAX(F10:F34),O23=150,K35<Sheet1!J40),4,IF(AND(95<=MAX(F10:F34),O23=150,K35<Sheet1!L40),5,IF(AND(95<=MAX(F10:F34),O23=150,K35<Sheet1!N40),6,IF(AND(95<=MAX(F10:F34),O23=150,K35<Sheet1!P40),7,IF(AND(95<=MAX(F10:F34),O23=150,K35<Sheet1!R40),8,IF(AND(95<=MAX(F10:F34),O23=150,K35<Sheet1!T40),9,IF(AND(95<=MAX(F10:F34),O23=150,K35<Sheet1!V40),10,IF(AND(95<=MAX(F10:F34),O23=200,K35<Sheet1!D41),1,IF(AND(95<=MAX(F10:F34),O23=200,K35<Sheet1!F41),2,IF(AND(95<=MAX(F10:F34),O23=200,K35<Sheet1!H41),3,IF(AND(95<=MAX(F10:F34),O23=200,K35<Sheet1!J41),4,IF(AND(95<=MAX(F10:F34),O23=200,K35<Sheet1!L41),5,IF(AND(95<=MAX(F10:F34),O23=200,K35<Sheet1!N41),6,IF(AND(95<=MAX(F10:F34),O23=200,K35<Sheet1!P41),7,IF(AND(95<=MAX(F10:F34),O23=200,K35<Sheet1!R41),8,IF(AND(95<=MAX(F10:F34),O23=200,K35<Sheet1!T41),9,IF(AND(95<=MAX(F10:F34),O23=200,K35<Sheet1!V41),10,IF(AND(95<=MAX(F10:F34),O23=225,K35<Sheet1!D42),1,IF(AND(95<=MAX(F10:F34),O23=225,K35<Sheet1!F42),2,IF(AND(95<=MAX(F10:F34),O23=225,K35<Sheet1!H42),3,IF(AND(95<=MAX(F10:F34),O23=225,K35<Sheet1!J42),4,IF(AND(95<=MAX(F10:F34),O23=225,K35<Sheet1!L42),5,IF(AND(95<=MAX(F10:F34),O23=225,K35<Sheet1!N42),6,IF(AND(95<=MAX(F10:F34),O23=225,K35<Sheet1!P42),7,IF(AND(95<=MAX(F10:F34),O23=225,K35<Sheet1!R42),8,IF(AND(95<=MAX(F10:F34),O23=225,K35<Sheet1!T42),9,IF(AND(95<=MAX(F10:F34),O23=225,K35<Sheet1!V42),10,IF(AND(95<=MAX(F10:F34),O23=300,K35<Sheet1!D43),1,IF(AND(95<=MAX(F10:F34),O23=300,K35<Sheet1!F43),2,IF(AND(95<=MAX(F10:F34),O23=300,K35<Sheet1!H43),3,IF(AND(95<=MAX(F10:F34),O23=300,K35<Sheet1!J43),4,IF(AND(95<=MAX(F10:F34),O23=300,K35<Sheet1!L43),5,IF(AND(95<=MAX(F10:F34),O23=300,K35<Sheet1!N43),6,IF(AND(95<=MAX(F10:F34),O23=300,K35<Sheet1!P43),7,IF(AND(95<=MAX(F10:F34),O23=300,K35<Sheet1!R43),8,IF(AND(95<=MAX(F10:F34),O23=300,K35<Sheet1!T43),9,IF(AND(95<=MAX(F10:F34),O23=300,K35<Sheet1!V43),10,FALSE)))))))))))))))))))))))))))))))))))))))))))))))))))))))))))) -> FALSE
C26: 17 | E26: Single core | F26: 50 | G26: mm2 | H26: =IF(AND($B$10="LV",E26="SINGLE CORE"),VLOOKUP('Cable TRAY VER.1.1'!F26,Sheet1!$E$4:$F$23,2,0),IF(AND($B$10="LV",E26="MULTI CORE"),VLOOKUP(F26,Sheet1!$A$4:$B$20,2,0),IF(AND('Cable TRAY VER.1.1'!$B$10="MV",'Cable TRAY VER.1.1'!E26="SINGLE CORE"),VLOOKUP('Cable TRAY VER.1.1'!F26,Sheet1!$A$70:$L$81,12,0),IF(AND('Cable TRAY VER.1.1'!$B$10="MV",'Cable TRAY VER.1.1'!E26="MULTI CORE"),VLOOKUP('Cable TRAY VER.1.1'!F26,Sheet1!$A$87:$L$95,12,0),FALSE)))) -> 36 | I26: =H26*D26 -> 0 | J26: =3.14*H26*H26/4 -> 1017.36 | K26: =J26*D26 -> 0 | P26: =IF(AND(95<=MAX(F10:F34),O23=400,K35<Sheet1!D44),1,IF(AND(95<=MAX(F10:F34),O23=400,K35<Sheet1!F44),2,IF(AND(95<=MAX(F10:F34),O23=400,K35<Sheet1!H44),3,IF(AND(95<=MAX(F10:F34),O23=400,K35<Sheet1!J44),4,IF(AND(95<=MAX(F10:F34),O23=400,K35<Sheet1!L44),5,IF(AND(95<=MAX(F10:F34),O23=400,K35<Sheet1!N44),6,IF(AND(95<=MAX(F10:F34),O23=400,K35<Sheet1!P44),7,IF(AND(95<=MAX(F10:F34),O23=400,K35<Sheet1!R44),8,IF(AND(95<=MAX(F10:F34),O23=400,K35<Sheet1!T44),9,IF(AND(95<=MAX(F10:F34),O23=400,K35<Sheet1!V44),10,IF(AND(95<=MAX(F10:F34),O23=450,K35<Sheet1!D45),1,IF(AND(95<=MAX(F10:F34),O23=450,K35<Sheet1!F45),2,IF(AND(95<=MAX(F10:F34),O23=450,K35<Sheet1!H45),3,IF(AND(95<=MAX(F10:F34),O23=450,K35<Sheet1!J45),4,IF(AND(95<=MAX(F10:F34),O23=450,K35<Sheet1!L45),5,IF(AND(95<=MAX(F10:F34),O23=450,K35<Sheet1!N45),6,IF(AND(95<=MAX(F10:F34),O23=450,K35<Sheet1!P45),7,IF(AND(95<=MAX(F10:F34),O23=450,K35<Sheet1!R45),8,IF(AND(95<=MAX(F10:F34),O23=450,K35<Sheet1!T45),9,IF(AND(95<=MAX(F10:F34),O23=450,K35<Sheet1!V45),10,IF(AND(95<=MAX(F10:F34),O23=500,K35<Sheet1!D46),1,IF(AND(95<=MAX(F10:F34),O23=500,K35<Sheet1!F46),2,IF(AND(95<=MAX(F10:F34),O23=500,K35<Sheet1!H46),3,IF(AND(95<=MAX(F10:F34),O23=500,K35<Sheet1!J46),4,IF(AND(95<=MAX(F10:F34),O23=500,K35<Sheet1!L46),5,IF(AND(95<=MAX(F10:F34),O23=500,K35<Sheet1!N46),6,IF(AND(95<=MAX(F10:F34),O23=500,K35<Sheet1!P46),7,IF(AND(95<=MAX(F10:F34),O23=500,K35<Sheet1!R46),8,IF(AND(95<=MAX(F10:F34),O23=500,K35<Sheet1!T46),9,IF(AND(95<=MAX(F10:F34),O23=500,K35<Sheet1!V46),10,IF(AND(95<=MAX(F10:F34),O23=600,K35<Sheet1!D47),1,IF(AND(95<=MAX(F10:F34),O23=600,K35<Sheet1!F47),2,IF(AND(95<=MAX(F10:F34),O23=600,K35<Sheet1!H47),3,IF(AND(95<=MAX(F10:F34),O23=600,K35<Sheet1!J47),4,IF(AND(95<=MAX(F10:F34),O23=600,K35<Sheet1!L47),5,IF(AND(95<=MAX(F10:F34),O23=600,K35<Sheet1!N47),6,IF(AND(95<=MAX(F10:F34),O23=600,K35<Sheet1!P47),7,IF(AND(95<=MAX(F10:F34),O23=600,K35<Sheet1!R47),8,IF(AND(95<=MAX(F10:F34),O23=600,K35<Sheet1!T47),9,IF(AND(95<=MAX(F10:F34),O23=600,K35<Sheet1!V47),10,IF(AND(95<=MAX(F10:F34),O23=750,K35<Sheet1!D48),1,IF(AND(95<=MAX(F10:F34),O23=750,K35<Sheet1!F48),2,IF(AND(95<=MAX(F10:F34),O23=750,K35<Sheet1!H48),3,IF(AND(95<=MAX(F10:F34),O23=750,K35<Sheet1!J48),4,IF(AND(95<=MAX(F10:F34),O23=750,K35<Sheet1!L48),5,IF(AND(95<=MAX(F10:F34),O23=750,K35<Sheet1!N48),6,IF(AND(95<=MAX(F10:F34),O23=750,K35<Sheet1!P48),7,IF(AND(95<=MAX(F10:F34),O23=750,K35<Sheet1!R48),8,IF(AND(95<=MAX(F10:F34),O23=750,K35<Sheet1!T48),9,IF(AND(95<=MAX(F10:F34),O23=750,K35<Sheet1!V48),10,IF(AND(95<=MAX(F10:F34),O23=900,K35<Sheet1!D49),1,IF(AND(95<=MAX(F10:F34),O23=900,K35<Sheet1!F49),2,IF(AND(95<=MAX(F10:F34),O23=900,K35<Sheet1!H49),3,IF(AND(95<=MAX(F10:F34),O23=900,K35<Sheet1!J49),4,IF(AND(95<=MAX(F10:F34),O23=900,K35<Sheet1!L49),5,IF(AND(95<=MAX(F10:F34),O23=900,K35<Sheet1!N49),6,IF(AND(95<=MAX(F10:F34),O23=900,K35<Sheet1!P49),7,IF(AND(95<=MAX(F10:F34),O23=900,K35<Sheet1!R49),8,IF(AND(95<=MAX(F10:F34),O23=900,K35<Sheet1!T49),9,IF(AND(95<=MAX(F10:F34),O23=900,K35<Sheet1!V49),10,FALSE)))))))))))))))))))))))))))))))))))))))))))))))))))))))))))) -> FALSE
C27: 18 | E27: Single core | F27: 50 | G27: mm2 | H27: =IF(AND($B$10="LV",E27="SINGLE CORE"),VLOOKUP('Cable TRAY VER.1.1'!F27,Sheet1!$E$4:$F$23,2,0),IF(AND($B$10="LV",E27="MULTI CORE"),VLOOKUP(F27,Sheet1!$A$4:$B$20,2,0),IF(AND('Cable TRAY VER.1.1'!$B$10="MV",'Cable TRAY VER.1.1'!E27="SINGLE CORE"),VLOOKUP('Cable TRAY VER.1.1'!F27,Sheet1!$A$70:$L$81,12,0),IF(AND('Cable TRAY VER.1.1'!$B$10="MV",'Cable TRAY VER.1.1'!E27="MULTI CORE"),VLOOKUP('Cable TRAY VER.1.1'!F27,Sheet1!$A$87:$L$95,12,0),FALSE)))) -> 36 | I27: =H27*D27 -> 0 | J27: =3.14*H27*H27/4 -> 1017.36 | K27: =J27*D27 -> 0 | P27: =MAX(P23:P26) -> 0
C28: 19 | E28: Single core | F28: 50 | G28: mm2 | H28: =IF(AND($B$10="LV",E28="SINGLE CORE"),VLOOKUP('Cable TRAY VER.1.1'!F28,Sheet1!$E$4:$F$23,2,0),IF(AND($B$10="LV",E28="MULTI CORE"),VLOOKUP(F28,Sheet1!$A$4:$B$20,2,0),IF(AND('Cable TRAY VER.1.1'!$B$10="MV",'Cable TRAY VER.1.1'!E28="SINGLE CORE"),VLOOKUP('Cable TRAY VER.1.1'!F28,Sheet1!$A$70:$L$81,12,0),IF(AND('Cable TRAY VER.1.1'!$B$10="MV",'Cable TRAY VER.1.1'!E28="MULTI CORE"),VLOOKUP('Cable TRAY VER.1.1'!F28,Sheet1!$A$87:$L$95,12,0),FALSE)))) -> 36 | I28: =H28*D28 -> 0 | J28: =3.14*H28*H28/4 -> 1017.36 | K28: =J28*D28 -> 0
C29: 20 | E29: Single core | F29: 50 | G29: mm2 | H29: =IF(AND($B$10="LV",E29="SINGLE CORE"),VLOOKUP('Cable TRAY VER.1.1'!F29,Sheet1!$E$4:$F$23,2,0),IF(AND($B$10="LV",E29="MULTI CORE"),VLOOKUP(F29,Sheet1!$A$4:$B$20,2,0),IF(AND('Cable TRAY VER.1.1'!$B$10="MV",'Cable TRAY VER.1.1'!E29="SINGLE CORE"),VLOOKUP('Cable TRAY VER.1.1'!F29,Sheet1!$A$70:$L$81,12,0),IF(AND('Cable TRAY VER.1.1'!$B$10="MV",'Cable TRAY VER.1.1'!E29="MULTI CORE"),VLOOKUP('Cable TRAY VER.1.1'!F29,Sheet1!$A$87:$L$95,12,0),FALSE)))) -> 36 | I29: =H29*D29 -> 0 | J29: =3.14*H29*H29/4 -> 1017.36 | K29: =J29*D29 -> 0
C30: 21 | E30: Single core | F30: 50 | G30: mm2 | H30: =IF(AND($B$10="LV",E30="SINGLE CORE"),VLOOKUP('Cable TRAY VER.1.1'!F30,Sheet1!$E$4:$F$23,2,0),IF(AND($B$10="LV",E30="MULTI CORE"),VLOOKUP(F30,Sheet1!$A$4:$B$20,2,0),IF(AND('Cable TRAY VER.1.1'!$B$10="MV",'Cable TRAY VER.1.1'!E30="SINGLE CORE"),VLOOKUP('Cable TRAY VER.1.1'!F30,Sheet1!$A$70:$L$81,12,0),IF(AND('Cable TRAY VER.1.1'!$B$10="MV",'Cable TRAY VER.1.1'!E30="MULTI CORE"),VLOOKUP('Cable TRAY VER.1.1'!F30,Sheet1!$A$87:$L$95,12,0),FALSE)))) -> 36 | I30: =H30*D30 -> 0 | J30: =3.14*H30*H30/4 -> 1017.36 | K30: =J30*D30 -> 0
C31: 22 | E31: Single core | F31: 50 | G31: mm2 | H31: =IF(AND($B$10="LV",E31="SINGLE CORE"),VLOOKUP('Cable TRAY VER.1.1'!F31,Sheet1!$E$4:$F$23,2,0),IF(AND($B$10="LV",E31="MULTI CORE"),VLOOKUP(F31,Sheet1!$A$4:$B$20,2,0),IF(AND('Cable TRAY VER.1.1'!$B$10="MV",'Cable TRAY VER.1.1'!E31="SINGLE CORE"),VLOOKUP('Cable TRAY VER.1.1'!F31,Sheet1!$A$70:$L$81,12,0),IF(AND('Cable TRAY VER.1.1'!$B$10="MV",'Cable TRAY VER.1.1'!E31="MULTI CORE"),VLOOKUP('Cable TRAY VER.1.1'!F31,Sheet1!$A$87:$L$95,12,0),FALSE)))) -> 36 | I31: =H31*D31 -> 0 | J31: =3.14*H31*H31/4 -> 1017.36 | K31: =J31*D31 -> 0
C32: 23 | E32: Single core | F32: 50 | G32: mm2 | H32: =IF(AND($B$10="LV",E32="SINGLE CORE"),VLOOKUP('Cable TRAY VER.1.1'!F32,Sheet1!$E$4:$F$23,2,0),IF(AND($B$10="LV",E32="MULTI CORE"),VLOOKUP(F32,Sheet1!$A$4:$B$20,2,0),IF(AND('Cable TRAY VER.1.1'!$B$10="MV",'Cable TRAY VER.1.1'!E32="SINGLE CORE"),VLOOKUP('Cable TRAY VER.1.1'!F32,Sheet1!$A$70:$L$81,12,0),IF(AND('Cable TRAY VER.1.1'!$B$10="MV",'Cable TRAY VER.1.1'!E32="MULTI CORE"),VLOOKUP('Cable TRAY VER.1.1'!F32,Sheet1!$A$87:$L$95,12,0),FALSE)))) -> 36 | I32: =H32*D32 -> 0 | J32: =3.14*H32*H32/4 -> 1017.36 | K32: =J32*D32 -> 0
C33: 24 | E33: Single core | F33: 50 | G33: mm2 | H33: =IF(AND($B$10="LV",E33="SINGLE CORE"),VLOOKUP('Cable TRAY VER.1.1'!F33,Sheet1!$E$4:$F$23,2,0),IF(AND($B$10="LV",E33="MULTI CORE"),VLOOKUP(F33,Sheet1!$A$4:$B$20,2,0),IF(AND('Cable TRAY VER.1.1'!$B$10="MV",'Cable TRAY VER.1.1'!E33="SINGLE CORE"),VLOOKUP('Cable TRAY VER.1.1'!F33,Sheet1!$A$70:$L$81,12,0),IF(AND('Cable TRAY VER.1.1'!$B$10="MV",'Cable TRAY VER.1.1'!E33="MULTI CORE"),VLOOKUP('Cable TRAY VER.1.1'!F33,Sheet1!$A$87:$L$95,12,0),FALSE)))) -> 36 | I33: =H33*D33 -> 0 | J33: =3.14*H33*H33/4 -> 1017.36 | K33: =J33*D33 -> 0
C34: 25 | E34: Multi core | F34: 50 | G34: mm2 | H34: =IF(AND($B$10="LV",E34="SINGLE CORE"),VLOOKUP('Cable TRAY VER.1.1'!F34,Sheet1!$E$4:$F$23,2,0),IF(AND($B$10="LV",E34="MULTI CORE"),VLOOKUP(F34,Sheet1!$A$4:$B$20,2,0),IF(AND('Cable TRAY VER.1.1'!$B$10="MV",'Cable TRAY VER.1.1'!E34="SINGLE CORE"),VLOOKUP('Cable TRAY VER.1.1'!F34,Sheet1!$A$70:$L$81,12,0),IF(AND('Cable TRAY VER.1.1'!$B$10="MV",'Cable TRAY VER.1.1'!E34="MULTI CORE"),VLOOKUP('Cable TRAY VER.1.1'!F34,Sheet1!$A$87:$L$95,12,0),FALSE)))) -> 64 | I34: =H34*D34 -> 0 | J34: =3.14*H34*H34/4 -> 3215.36 | K34: =J34*D34 -> 0
H35: =SUM(H10:H34) -> 1033 | I35: =SUM(I10:I34) -> 9618 | K35: =SUM(K10:K34) -> 713966.92
A36: " وَقُلِ اعْمَلُوا فَسَيَرَى اللَّهُ عَمَلَكُمْ وَرَسُولُهُ وَالْمُؤْمِنُونَ" “And say (unto them): Act! Allah will behold your actions, and (so will) His messenger and the believers,” Suraht At-Taubah (105)
A37: By: Eng. Mohamed Sleem moh.aly.sleem@gmail.com

Sheet Sheet3
